<?xml version="1.0" ?>
<robot xmlns:xacro="http://ros.org/wiki/xacro">

  <xacro:macro name="create_wheel" params="prefix y_offset wheel_radius wheel_width">
    <link name="${prefix}_wheel_link">
    <inertial>
      <origin xyz="0 0 0" />
      <mass value="0.01" />
      <inertia ixx="0.001" ixy="0.0" ixz="0.0" iyy="0.001" iyz="0.0" izz="0.001" />
    </inertial>

    <visual>
      <origin xyz="0 0 0" rpy="0 ${pi/2} ${pi/2}" />
      <geometry>
        <cylinder radius="${wheel_radius}" length="${wheel_width}" />
      </geometry>
    </visual>

    <collision>
      <origin xyz="0 0 0" rpy="0 ${pi/2} ${pi/2}" />
      <geometry>
        <cylinder radius="${wheel_radius}" length="${wheel_width}" />
      </geometry>
    </collision>
    </link>

   <joint name="${prefix}_wheel_joint" type="continuous">
      <origin xyz="0 ${y_offset} 0.015" rpy="0 0 0" />
      <parent link="base_link" />
      <child link="${prefix}_wheel_link" />
      <axis xyz="0 1 0" />
    </joint>
  </xacro:macro>

</robot>